2019-09-21 12:58:53,520 ERROR: Unhandled exception [in ./app/tasks.py:48]
Traceback (most recent call last):
  File "./app/tasks.py", line 45, in export_posts
    sync=True)
  File "./app/email.py", line 21, in send_email
    mail.send(msg)
  File "/home/alexey/PycharmProjects/flask_site/venv/lib/python3.7/site-packages/flask_mail.py", line 491, in send
    with self.connect() as connection:
  File "/home/alexey/PycharmProjects/flask_site/venv/lib/python3.7/site-packages/flask_mail.py", line 144, in __enter__
    self.host = self.configure_host()
  File "/home/alexey/PycharmProjects/flask_site/venv/lib/python3.7/site-packages/flask_mail.py", line 158, in configure_host
    host = smtplib.SMTP(self.mail.server, self.mail.port)
  File "/usr/lib/python3.7/smtplib.py", line 251, in __init__
    (code, msg) = self.connect(host, port)
  File "/usr/lib/python3.7/smtplib.py", line 336, in connect
    self.sock = self._get_socket(host, port, self.timeout)
  File "/usr/lib/python3.7/smtplib.py", line 307, in _get_socket
    self.source_address)
  File "/usr/lib/python3.7/socket.py", line 727, in create_connection
    raise err
  File "/usr/lib/python3.7/socket.py", line 716, in create_connection
    sock.connect(sa)
ConnectionRefusedError: [Errno 111] Connection refused
2019-09-21 23:26:12,863 INFO: Microblog startup [in /home/alexey/PycharmProjects/flask_site/app/__init__.py:81]
2019-09-21 23:29:34,459 INFO: Microblog startup [in /home/alexey/PycharmProjects/flask_site/app/__init__.py:81]
2019-09-22 11:17:00,978 INFO: Microblog startup [in /home/alexey/PycharmProjects/flask_site/app/__init__.py:81]
2019-09-22 13:02:50,204 INFO: Microblog startup [in ./app/__init__.py:81]
2019-09-22 13:04:41,092 ERROR: Unhandled exception [in ./app/tasks.py:48]
Traceback (most recent call last):
  File "./app/tasks.py", line 45, in export_posts
    sync=True)
  File "./app/email.py", line 21, in send_email
    mail.send(msg)
  File "/home/alexey/PycharmProjects/flask_site/venv/lib/python3.7/site-packages/flask_mail.py", line 491, in send
    with self.connect() as connection:
  File "/home/alexey/PycharmProjects/flask_site/venv/lib/python3.7/site-packages/flask_mail.py", line 144, in __enter__
    self.host = self.configure_host()
  File "/home/alexey/PycharmProjects/flask_site/venv/lib/python3.7/site-packages/flask_mail.py", line 158, in configure_host
    host = smtplib.SMTP(self.mail.server, self.mail.port)
  File "/usr/lib/python3.7/smtplib.py", line 251, in __init__
    (code, msg) = self.connect(host, port)
  File "/usr/lib/python3.7/smtplib.py", line 336, in connect
    self.sock = self._get_socket(host, port, self.timeout)
  File "/usr/lib/python3.7/smtplib.py", line 307, in _get_socket
    self.source_address)
  File "/usr/lib/python3.7/socket.py", line 727, in create_connection
    raise err
  File "/usr/lib/python3.7/socket.py", line 716, in create_connection
    sock.connect(sa)
ConnectionRefusedError: [Errno 111] Connection refused
2019-09-28 11:59:02,527 INFO: Microblog startup [in /home/alexey/PycharmProjects/flask_site/app/__init__.py:84]
2019-09-28 11:59:18,287 ERROR: Exception on /api/users/1 [GET] [in /home/alexey/PycharmProjects/flask_site/venv/lib/python3.7/site-packages/flask/app.py:1761]
Traceback (most recent call last):
  File "/home/alexey/PycharmProjects/flask_site/venv/lib/python3.7/site-packages/flask/app.py", line 2292, in wsgi_app
    response = self.full_dispatch_request()
  File "/home/alexey/PycharmProjects/flask_site/venv/lib/python3.7/site-packages/flask/app.py", line 1815, in full_dispatch_request
    rv = self.handle_user_exception(e)
  File "/home/alexey/PycharmProjects/flask_site/venv/lib/python3.7/site-packages/flask/app.py", line 1718, in handle_user_exception
    reraise(exc_type, exc_value, tb)
  File "/home/alexey/PycharmProjects/flask_site/venv/lib/python3.7/site-packages/flask/_compat.py", line 35, in reraise
    raise value
  File "/home/alexey/PycharmProjects/flask_site/venv/lib/python3.7/site-packages/flask/app.py", line 1813, in full_dispatch_request
    rv = self.dispatch_request()
  File "/home/alexey/PycharmProjects/flask_site/venv/lib/python3.7/site-packages/flask/app.py", line 1799, in dispatch_request
    return self.view_functions[rule.endpoint](**req.view_args)
  File "/home/alexey/PycharmProjects/flask_site/app/api/users.py", line 8, in get_user
    return jsonify(User.query.get_or_404(id).to_dict())
  File "/home/alexey/PycharmProjects/flask_site/app/models.py", line 191, in to_dict
    'last_seen': self.last_seen.isoformat() + 'Z',
AttributeError: 'NoneType' object has no attribute 'isoformat'
2019-09-28 12:00:46,505 ERROR: Exception on /api/users/1 [GET] [in /home/alexey/PycharmProjects/flask_site/venv/lib/python3.7/site-packages/flask/app.py:1761]
Traceback (most recent call last):
  File "/home/alexey/PycharmProjects/flask_site/venv/lib/python3.7/site-packages/flask/app.py", line 2292, in wsgi_app
    response = self.full_dispatch_request()
  File "/home/alexey/PycharmProjects/flask_site/venv/lib/python3.7/site-packages/flask/app.py", line 1815, in full_dispatch_request
    rv = self.handle_user_exception(e)
  File "/home/alexey/PycharmProjects/flask_site/venv/lib/python3.7/site-packages/flask/app.py", line 1718, in handle_user_exception
    reraise(exc_type, exc_value, tb)
  File "/home/alexey/PycharmProjects/flask_site/venv/lib/python3.7/site-packages/flask/_compat.py", line 35, in reraise
    raise value
  File "/home/alexey/PycharmProjects/flask_site/venv/lib/python3.7/site-packages/flask/app.py", line 1813, in full_dispatch_request
    rv = self.dispatch_request()
  File "/home/alexey/PycharmProjects/flask_site/venv/lib/python3.7/site-packages/flask/app.py", line 1799, in dispatch_request
    return self.view_functions[rule.endpoint](**req.view_args)
  File "/home/alexey/PycharmProjects/flask_site/app/api/users.py", line 8, in get_user
    return jsonify(User.query.get_or_404(id).to_dict())
  File "/home/alexey/PycharmProjects/flask_site/app/models.py", line 191, in to_dict
    'last_seen': self.last_seen.isoformat() + 'Z',
AttributeError: 'NoneType' object has no attribute 'isoformat'
2019-09-28 12:05:18,307 INFO: Microblog startup [in /home/alexey/PycharmProjects/flask_site/app/__init__.py:84]
2019-09-28 12:11:45,038 INFO: Microblog startup [in /home/alexey/PycharmProjects/flask_site/app/__init__.py:84]
2019-09-28 12:13:47,402 INFO: Microblog startup [in /home/alexey/PycharmProjects/flask_site/app/__init__.py:84]
2019-09-28 12:16:00,197 INFO: Microblog startup [in /home/alexey/PycharmProjects/flask_site/app/__init__.py:84]
2019-09-28 12:22:23,549 INFO: Microblog startup [in /home/alexey/PycharmProjects/flask_site/app/__init__.py:84]
2019-09-28 12:22:55,998 INFO: Microblog startup [in /home/alexey/PycharmProjects/flask_site/app/__init__.py:84]
2019-09-28 12:50:48,088 ERROR: Exception on /api/users [GET] [in /home/alexey/PycharmProjects/flask_site/venv/lib/python3.7/site-packages/flask/app.py:1761]
Traceback (most recent call last):
  File "/home/alexey/PycharmProjects/flask_site/venv/lib/python3.7/site-packages/flask/app.py", line 2292, in wsgi_app
    response = self.full_dispatch_request()
  File "/home/alexey/PycharmProjects/flask_site/venv/lib/python3.7/site-packages/flask/app.py", line 1816, in full_dispatch_request
    return self.finalize_request(rv)
  File "/home/alexey/PycharmProjects/flask_site/venv/lib/python3.7/site-packages/flask/app.py", line 1831, in finalize_request
    response = self.make_response(rv)
  File "/home/alexey/PycharmProjects/flask_site/venv/lib/python3.7/site-packages/flask/app.py", line 1957, in make_response
    'The view function did not return a valid response. The'
TypeError: The view function did not return a valid response. The function either returned None or ended without a return statement.
2019-09-28 12:52:58,035 ERROR: Exception on /api/users [GET] [in /home/alexey/PycharmProjects/flask_site/venv/lib/python3.7/site-packages/flask/app.py:1761]
Traceback (most recent call last):
  File "/home/alexey/PycharmProjects/flask_site/venv/lib/python3.7/site-packages/flask/app.py", line 2292, in wsgi_app
    response = self.full_dispatch_request()
  File "/home/alexey/PycharmProjects/flask_site/venv/lib/python3.7/site-packages/flask/app.py", line 1816, in full_dispatch_request
    return self.finalize_request(rv)
  File "/home/alexey/PycharmProjects/flask_site/venv/lib/python3.7/site-packages/flask/app.py", line 1831, in finalize_request
    response = self.make_response(rv)
  File "/home/alexey/PycharmProjects/flask_site/venv/lib/python3.7/site-packages/flask/app.py", line 1957, in make_response
    'The view function did not return a valid response. The'
TypeError: The view function did not return a valid response. The function either returned None or ended without a return statement.
2019-09-28 12:54:07,667 ERROR: Exception on /api/users [GET] [in /home/alexey/PycharmProjects/flask_site/venv/lib/python3.7/site-packages/flask/app.py:1761]
Traceback (most recent call last):
  File "/home/alexey/PycharmProjects/flask_site/venv/lib/python3.7/site-packages/flask/app.py", line 2292, in wsgi_app
    response = self.full_dispatch_request()
  File "/home/alexey/PycharmProjects/flask_site/venv/lib/python3.7/site-packages/flask/app.py", line 1816, in full_dispatch_request
    return self.finalize_request(rv)
  File "/home/alexey/PycharmProjects/flask_site/venv/lib/python3.7/site-packages/flask/app.py", line 1831, in finalize_request
    response = self.make_response(rv)
  File "/home/alexey/PycharmProjects/flask_site/venv/lib/python3.7/site-packages/flask/app.py", line 1957, in make_response
    'The view function did not return a valid response. The'
TypeError: The view function did not return a valid response. The function either returned None or ended without a return statement.
